<?xml version="1.0" encoding="UTF-8"?>
<!-- Generated by org.testng.reporters.JUnitReportReporter -->
<testsuite hostname="NISANTH" failures="2" tests="2" name="com.trello.qsipders.learntestng.SoftAssertAutomationScript" time="62.838" errors="0" timestamp="2023-03-28T21:43:44 IST" skipped="0">
  <testcase classname="com.trello.qsipders.learntestng.SoftAssertAutomationScript" name="checkLogOut" time="26.700">
    <failure message="The script fail due to
	expected [https:/demo.actitime.com/login.do] but found [https://demo.actitime.com/login.do]" type="java.lang.AssertionError">
      <![CDATA[java.lang.AssertionError: The script fail due to
expected [https:/demo.actitime.com/login.do] but found [https://demo.actitime.com/login.do]
at org.testng.asserts.SoftAssert.assertAll(SoftAssert.java:46)
at com.trello.qsipders.learntestng.SoftAssertAutomationScript.checkLogOut(SoftAssertAutomationScript.java:67)
at java.base/jdk.internal.reflect.DirectMethodHandleAccessor.invoke(DirectMethodHandleAccessor.java:104)
at java.base/java.lang.reflect.Method.invoke(Method.java:578)
at org.testng.internal.invokers.MethodInvocationHelper.invokeMethod(MethodInvocationHelper.java:139)
at org.testng.internal.invokers.TestInvoker.invokeMethod(TestInvoker.java:677)
at org.testng.internal.invokers.TestInvoker.invokeTestMethod(TestInvoker.java:221)
at org.testng.internal.invokers.MethodRunner.runInSequence(MethodRunner.java:50)
at org.testng.internal.invokers.TestInvoker$MethodInvocationAgent.invoke(TestInvoker.java:969)
at org.testng.internal.invokers.TestInvoker.invokeTestMethods(TestInvoker.java:194)
at org.testng.internal.invokers.TestMethodWorker.invokeTestMethods(TestMethodWorker.java:148)
at org.testng.internal.invokers.TestMethodWorker.run(TestMethodWorker.java:128)
at java.base/java.util.ArrayList.forEach(ArrayList.java:1511)
at org.testng.TestRunner.privateRun(TestRunner.java:829)
at org.testng.TestRunner.run(TestRunner.java:602)
at org.testng.SuiteRunner.runTest(SuiteRunner.java:437)
at org.testng.SuiteRunner$SuiteWorker.run(SuiteRunner.java:475)
at org.testng.internal.thread.ThreadUtil.lambda$execute$0(ThreadUtil.java:58)
at java.base/java.util.concurrent.FutureTask.run(FutureTask.java:317)
at java.base/java.util.concurrent.ThreadPoolExecutor.runWorker(ThreadPoolExecutor.java:1144)
at java.base/java.util.concurrent.ThreadPoolExecutor$Worker.run(ThreadPoolExecutor.java:642)
at java.base/java.lang.Thread.run(Thread.java:1589)
]]>
    </failure>
  </testcase> <!-- checkLogOut -->
  <system-out>
    <![CDATA[Login Successfull
Home page is displayed
Logout Successful]]>
  </system-out>
  <testcase classname="com.trello.qsipders.learntestng.SoftAssertAutomationScript" name="checkLogOut" time="36.138">
    <failure message="The script fail due to
	expected [https:/demo.actitime.com/login.do] but found [https://demo.actitime.com/login.do]" type="java.lang.AssertionError">
      <![CDATA[java.lang.AssertionError: The script fail due to
expected [https:/demo.actitime.com/login.do] but found [https://demo.actitime.com/login.do]
at org.testng.asserts.SoftAssert.assertAll(SoftAssert.java:46)
at com.trello.qsipders.learntestng.SoftAssertAutomationScript.checkLogOut(SoftAssertAutomationScript.java:67)
at java.base/jdk.internal.reflect.DirectMethodHandleAccessor.invoke(DirectMethodHandleAccessor.java:104)
at java.base/java.lang.reflect.Method.invoke(Method.java:578)
at org.testng.internal.invokers.MethodInvocationHelper.invokeMethod(MethodInvocationHelper.java:139)
at org.testng.internal.invokers.TestInvoker.invokeMethod(TestInvoker.java:677)
at org.testng.internal.invokers.TestInvoker.invokeTestMethod(TestInvoker.java:221)
at org.testng.internal.invokers.MethodRunner.runInSequence(MethodRunner.java:50)
at org.testng.internal.invokers.TestInvoker$MethodInvocationAgent.invoke(TestInvoker.java:969)
at org.testng.internal.invokers.TestInvoker.invokeTestMethods(TestInvoker.java:194)
at org.testng.internal.invokers.TestMethodWorker.invokeTestMethods(TestMethodWorker.java:148)
at org.testng.internal.invokers.TestMethodWorker.run(TestMethodWorker.java:128)
at java.base/java.util.ArrayList.forEach(ArrayList.java:1511)
at org.testng.TestRunner.privateRun(TestRunner.java:829)
at org.testng.TestRunner.run(TestRunner.java:602)
at org.testng.SuiteRunner.runTest(SuiteRunner.java:437)
at org.testng.SuiteRunner$SuiteWorker.run(SuiteRunner.java:475)
at org.testng.internal.thread.ThreadUtil.lambda$execute$0(ThreadUtil.java:58)
at java.base/java.util.concurrent.FutureTask.run(FutureTask.java:317)
at java.base/java.util.concurrent.ThreadPoolExecutor.runWorker(ThreadPoolExecutor.java:1144)
at java.base/java.util.concurrent.ThreadPoolExecutor$Worker.run(ThreadPoolExecutor.java:642)
at java.base/java.lang.Thread.run(Thread.java:1589)
]]>
    </failure>
  </testcase> <!-- checkLogOut -->
  <system-out>
    <![CDATA[Login Successfull
Home page is displayed
Logout Successful]]>
  </system-out>
</testsuite> <!-- com.trello.qsipders.learntestng.SoftAssertAutomationScript -->
